Workbook

Sheet Cats & Hats Intro
B2: Welcome to Cats & Hats. An adoptable collection game where you collect more hats than cats.
B4: Getting Started
B5: This adoptable game is played through the Secundi Discord in the #cats-n-hats channel. You begin by filling out a form to select a starter Cat and starter Hat. You'll get your very own Closet (a Sheet in this document) that gets updated with everything you collect.
B7: Hats
B8: Every day you get open the Mysterious Hat Box that will contain a random hat from the available pool. This is done through the Discord Channel. You might get a duplicate, but don't worry, try to trade it to someone else for a hat you don't have. Check out the 'Catalog' Sheet to see all the hats! (Or don't and let yourself be surprised. 😉) Hats come in Sets that usually have a theme. Collecting multiple hats in a Set will reward you greatly!
B9: The current available sets are: - Starter - Basic - Animals
B10: Reaching certain milestone within a Set will earn you rewards such as Shards and exclusive hats! Rewards for set completion are automatically added to your Closet. You may trade away hats that contributed to that reward, but you won't receive the reward a second time when you hit the milestone again. Check the Hat Brochure to see what the milestones and their rewards are.
B12: Cat Colours
B13: Cat colours work like Neopet paintbrushes (with infinite uses). When you 'dress up', you can select a hat and a cat colour. Cat colours are gained through events.
B15: Weekly Dress Up Event
B16: Every week there's a fancy event where you get to show off your latest finds. Submit the cat colour and hat you'd like to wear to the event. Participation will reward you with Shards or even Hats and Colours.
B18: Shards & Disenchanting
B19: Shards (💎) are the basic currency for Cat & Hats. Have too many Hats? Closet feeling a little cluttered? Disenchant your unwanted Hats for some shards! Disenchanted hats will disappear from your collection but grant you # shards. There is also a chance of getting a handful of shards when you open the Mystery Box.

Sheet Hat Brochure
C2: =Hats!$A$2 -> Starter
C4: =image(Hats!$F$2, 3) | D4: =Hats!$B$2 -> Cap, Navy | F4: =image(Hats!$F$3, 3) | G4: =Hats!$B$3 -> Beret, Maroon | I4: =image(Hats!$F$4, 3) | J4: =Hats!$B$4 -> Bucket Hat, Orange | L4: =image(Hats!$F$5, 3) | M4: =Hats!$B$5 -> Top Hat, Black
D5: =Hats!$C$2 -> AA01 | G5: =Hats!$C$3 -> AA02 | J5: =Hats!$C$4 -> AA03 | M5: =Hats!$C$5 -> AA04
D6: =Hats!$D$2 -> For sun protection or fashion? | G6: =Hats!$D$3 -> Oui, Oui. | J6: =Hats!$D$4 -> I hear they're hip these days. | M6: =Hats!$D$5 -> No pidgeons included.
C9: =Hats!$A$6 -> Basic
E11: Completion Rewards: 🎁 Collecting 6 Hats (50%) -- Choice of Basic paintbrush & 50 shards 🎁 Collecting 12 Hats (100%) -- ? & 200 shards
C13: =image(Hats!$F$6, 3) | D13: =Hats!$B$6 -> Ribbon, Red | F13: =image(Hats!$F$7, 3) | G13: =Hats!$B$7 -> Ribbon, Yellow | I13: =image(Hats!$F$8, 3) | J13: =Hats!$B$8 -> Cap, Black | L13: =image(Hats!$F$9, 3) | M13: =Hats!$B$9 -> Cap, Red
D14: =Hats!$C$6 -> AB01 | G14: =Hats!$C$7 -> AB02 | J14: =Hats!$C$8 -> AB03 | M14: =Hats!$C$9 -> AB04
D15: =Hats!$D$6 -> A pretty bow for your pretty head. | G15: =Hats!$D$7 -> An accessory for a summer day picnic. | J15: =Hats!$D$8 | M15: =Hats!$D$9
C17: =image(Hats!$F$10, 3) | D17: =Hats!$B$10 -> Party Hat, White | F17: =image(Hats!$F$11, 3) | G17: =Hats!$B$11 -> Party Hat, Blue | I17: =image(Hats!$F$12, 3) | J17: =Hats!$B$12 -> Party Hat, Green | L17: =image(Hats!$F$13, 3) | M17: =Hats!$B$13 -> Party Hat, Red
D18: =Hats!$C$10 -> AB05 | G18: =Hats!$C$11 -> AB06 | J18: =Hats!$C$12 -> AB07 | M18: =Hats!$C$13 -> AB08
D19: =Hats!$D$10 | G19: =Hats!$D$11 | J19: =Hats!$D$11 | M19: =Hats!$D$11
C21: =image(Hats!$F$14, 3) | D21: =Hats!$B$14 -> Sprout | F21: =image(Hats!$F$15, 3) | G21: =Hats!$B$15 -> Face Mask | I21: =image(Hats!$F$16, 3) | J21: =Hats!$B$16 -> Barrette, Pink | L21: =image(Hats!$F$17, 3) | M21: =Hats!$B$17 -> Barrette, Purple
D22: =Hats!$C$14 -> AB09 | G22: =Hats!$C$15 -> AB10 | J22: =Hats!$C$16 -> AB11 | M22: =Hats!$C$17 -> AB12
D23: =Hats!$D$14 | G23: =Hats!$D$15 -> 6 feet, please! | J23: =Hats!$D$16 | M23: =Hats!$D$17
C26: =Hats!$A$18 -> Animals
E28: Completion Rewards: 🎁 Collecting 9 Hats (50%) -- Exclusive hat & 50 shards 🎁 Collecting 19 Hats (100%) -- Exclusive hat & 200 shards
C30: =image(Hats!$F$18, 3) | D30: =Hats!$B$18 -> Bunny, Pink | F30: =image(Hats!$F$19, 3) | G30: =Hats!$B$19 -> Bunny, Pink Bows | I30: =image(Hats!$F$20, 3) | J30: =Hats!$B$20 -> Bunny, Blue | L30: =image(Hats!$F$21, 3) | M30: =Hats!$B$21 -> Bunny, Blue Bows
D31: =Hats!$C$18 -> AC01 | G31: =Hats!$C$19 -> AC02 | J31: =Hats!$C$20 -> AC03 | M31: =Hats!$C$21 -> AC04
D32: =Hats!$D$18 -> Pink and fluffy bunny ears. | G32: =Hats!$D$19 -> Pink and fluffy bunny ears. Adorned with little bows. | J32: =Hats!$D$20 -> Blue and fluffy bunny ears. | M32: =Hats!$D$21 -> Blue and fluffy bunny ears. Adorned with little bows.
C34: =image(Hats!$F$22, 3) | D34: =Hats!$B$22 -> Froggy, Green | F34: =image(Hats!$F$23, 3) | G34: =Hats!$B$23 -> Froggy, Toad | I34: =image(Hats!$F$24, 3) | J34: =Hats!$B$24 -> Froggy, Aqua | L34: =image(Hats!$F$25, 3) | M34: =Hats!$B$25 -> Ducky
D35: =Hats!$C$22 -> AC05 | G35: =Hats!$C$23 -> AC06 | J35: =Hats!$C$24 -> AC07 | M35: =Hats!$C$25 -> AC08
D36: =Hats!$D$22 -> Ribbit. | G36: =Hats!$D$23 -> Croak. | J36: =Hats!$D$24 -> Is he poisonous? | M36: =Hats!$D$25 -> Cleaning Instructions: Hand wash in a bubble bath.
C38: =image(Hats!$F$26, 3) | D38: =Hats!$B$26 -> Teddy, Brown | F38: =image(Hats!$F$27, 3) | G38: =Hats!$B$27 -> Teddy, Brown Ribbon | I38: =image(Hats!F28, 3) | J38: =Hats!$B$28 -> Teddy, White | L38: =image(Hats!$F$29, 3) | M38: =Hats!$B$29 -> Teddy, White Ribbon
D39: =Hats!$C$26 -> AC09 | G39: =Hats!$C$27 -> AC10 | J39: =Hats!$C$28 -> AC11 | M39: =Hats!$C$29 -> AC12
D40: =Hats!$D$26 -> Soft and cuddly. | G40: =Hats!$D$27 -> 🐻🎀 | J40: =Hats!$D$28 -> Soft and cuddly, but winter themed. | M40: =Hats!$D$29 -> 🐻‍❄️🎀
C42: =image(Hats!$F$30, 3) | D42: =Hats!$B$30 -> Piggy | F42: =image(Hats!$F$31, 3) | G42: =Hats!$B$31 -> Cow | I42: =image(Hats!$F$32, 3) | J42: =Hats!$B$32 -> Horse | L42: =image(Hats!$F$33, 3) | M42: =Hats!$B$33 -> Deer
D43: =Hats!$C$30 -> AC13 | G43: =Hats!$C$31 -> AC14 | J43: =Hats!$C$32 -> AC15 | M43: =Hats!$C$33 -> AC16
D44: =Hats!$D$30 -> Smells slightly like maple ham. | G44: =Hats!$D$31 -> Moo. | J44: =Hats!$D$32 -> Has a very fashionable mane. | M44: =Hats!$D$33 -> Loves you deer-ly.
C46: =image(Hats!$F$34, 3) | D46: =Hats!$B$34 -> Red Panda | F46: =image(Hats!$F$35, 3) | G46: =Hats!$B$35 -> Raccoon | I46: =image(Hats!$F$36, 3) | J46: =Hats!$B$36 -> Froggy, Crown | L46: =image(Hats!$F$37, 3) | M46: =Hats!$B$37 -> Unicorn
D47: =Hats!$C$34 -> AC17 | G47: =Hats!$C$35 -> AC18 | J47: =Hats!$C$36 -> AC19 | M47: =Hats!$C$37 -> AC20
D48: =Hats!$D$34 -> Fills you with raging teenager hormones. | G48: =Hats!$D$35 -> Makes you look vicious. | J48: =Hats!$D$36 -> 🎁 Reward. (solemnly) Ribbit. | M48: =Hats!$D$37 -> 🎁 Reward. Very magical!
C51: =Hats!$A$38 -> April Fools 2022
C53: =image(Hats!$F$38, 3) | D53: =Hats!$B$38 -> Googly Eyes | F53: =image(Hats!$F$39, 3) | G53: =Hats!$B$39 -> Jester Hat
D54: =Hats!$C$38 -> AD01 | G54: =Hats!$C$39 -> AD02
D55: =Hats!$D$38 -> You can make anything silly with googly eyes. | G55: =Hats!$D$39 -> Jingles when you laugh.

Sheet CATalog
C2: =Cats!$A$2 -> Starter
C4: =image(Cats!$E$2, 3) | D4: =Cats!$B$2 -> Black | F4: =image(Cats!$E$3, 3) | G4: =Cats!$B$3 -> White | I4: =image(Cats!$E$4, 3) | J4: =Cats!$B$4 -> Grey | L4: =image(Cats!$E$5, 3) | M4: =Cats!$B$5 -> Orange
D5: =Cats!$C$2 -> *A01 | G5: =Cats!$C$3 -> *A02 | J5: =Cats!$C$4 -> *A03 | M5: =Cats!$C$5 -> *A04
D6: =Cats!$D$2 -> Your typical house panther. | G6: =Cats!$D$3 -> Likes to nap on blankets. | J6: =Cats!$D$4 -> Very playful. | M6: =Cats!$D$5 -> Extremely food motivated.
C9: =Cats!$A$6 -> Basic
C11: =image(Cats!$E$6, 3) | D11: =Cats!$B$6 -> Tabby, Grey | F11: =image(Cats!$E$7, 3) | G11: =Cats!$B$7 -> Tabby, Brown | I11: =image(Cats!$E$8, 3) | J11: =Cats!$B$8 -> Tabby, Orange | L11: =image(Cats!$E$9, 3) | M11: =Cats!$B$9 -> Tabby, Torbie
D12: =Cats!$C$6 -> *B01 | G12: =Cats!$C$7 -> *B02 | J12: =Cats!$C$8 -> *B03 | M12: =Cats!$C$9 -> *B04
D13: =Cats!$D$6 -> Likes to push things off tables. | G13: =Cats!$D$7 -> Will climb anything, people included. | J13: =Cats!$D$8 -> Never stops meowing. | M13: =Cats!$D$9 -> Loves you... when they feel like it!
C15: =image(Cats!$E$10, 3) | D15: =Cats!$B$10 -> Calico, A | F15: =image(Cats!$E$11, 3) | G15: =Cats!$B$11 -> Calico, B | I15: =image(Cats!$E$12, 3) | J15: =Cats!$B$12 -> Calico, C | L15: =image(Cats!$E$13, 3) | M15: =Cats!$B$13 -> Calico, D
D16: =Cats!$C$10 -> *B05 | G16: =Cats!$C$11 -> *B06 | J16: =Cats!$C$12 -> *B07 | M16: =Cats!$C$13 -> *B08
D17: =Cats!$D$10 -> ZOOMIES. | G17: =Cats!$D$11 -> Likes to nap upside down. | J17: =Cats!$D$12 -> Likes sunny windowsills. | M17: =Cats!$D$13 -> Prefers chicken over salmon.
C19: =image(Cats!$E$14, 3) | D19: =Cats!$B$14 -> Calico, E | F19: =image(Cats!$E$15, 3) | G19: =Cats!$B$15 -> Calico, F | I19: =image(Cats!$E$16, 3) | J19: =Cats!$B$16 -> Calico, G | L19: =image(Cats!$E$17, 3) | M19: =Cats!$B$17 -> Calico, H
D20: =Cats!$C$14 -> *B09 | G20: =Cats!$C$15 -> *B10 | J20: =Cats!$C$16 -> *B11 | M20: =Cats!$C$17 -> *B12
D21: =Cats!$D$14 | G21: =Cats!$D$15 | J21: =Cats!$D$16 | M21: =Cats!$D$17
C24: =Cats!$A$18 -> Shop Exclusive
C26: =image(Cats!$E$18, 3) | D26: =Cats!$B$18 -> Galaxy | F26: =image(Cats!$E$19, 3) | G26: =Cats!$B$19 -> Glass | I26: =image(Cats!$E$20, 3) | J26: =Cats!$B$20 -> Meadow | L26: =image(Cats!$E$21, 3) | M26: =Cats!$B$21 -> Magma
D27: =Cats!$C$18 -> *C01 | G27: =Cats!$C$19 -> *C02 | J27: =Cats!$C$20 -> *C03 | M27: =Cats!$C$21 -> *C04
D28: =Cats!$D$18 -> Twinkles. | G28: =Cats!$D$19 -> Tinkles. | J28: =Cats!$D$20 -> Smells like fresh grass. | M28: =Cats!$D$21 -> Hot, hot, HOT!

Sheet Fashion Show
F3: =date(2022, 4, 4) -> 44655
F4: Theme: Whatever strikes your fancy! Reward: Your choice of a Cat Colour from the Basic set. 10 Shards.
C6: =SeaCrest!$J$10 | F6: =Springacres!$J$10 | I6: =Pinkshadow!$J$10 | L6: ='Luv007'!$J$10 | O6: =Ryuukokoro!$J$10 | R6: =Saturnalia!$J$10
C7: SeaCrest | F7: Springacres | I7: Pinkshadow | L7: Luv007 | O7: Ryuukokoro | R7: Saturnalia
C8: =IMAGE(Cats!$F$6, 3) | D8: =IMAGE(Hats!$G$11, 3) | F8: =IMAGE(Cats!$F$9, 3) | G8: =IMAGE(Hats!$G$30, 3) | I8: =IMAGE(Cats!$F$9, 3) | J8: =IMAGE(Hats!$G$7, 3) | L8: =IMAGE(Cats!$F$9, 3) | M8: =IMAGE(Hats!$G$35, 3) | O8: =IMAGE(Cats!$F$2, 3) | P8: =IMAGE(Hats!$G$35, 3) | R8: =IMAGE(Cats!$F$4, 3) | S8: =IMAGE(Hats!$G$38, 3)
C10: =XLostxDestinyX!$J$10 | F10: =Aralie!$J$10 | I10: =YLO!$J$10
C11: XLostxDestinyX | F11: Aralie | I11: YLO
C12: =IMAGE(Cats!$F$9, 3) | D12: =IMAGE(Hats!$G$33, 3) | F12: =IMAGE(Cats!$F$9, 3) | G12: =IMAGE(Hats!$G$35, 3) | I12: =IMAGE(Cats!$F$7, 3) | J12: =IMAGE(Hats!$G$10, 3)
F16: =date(2022, 3, 27) -> 44647
F17: Theme: Whatever strikes your fancy! Reward: Your choice of a Cat Colour from the Basic set. 10 Shards.
C19: =Springacres!$F$10 | F19: =Pinkshadow!$B$10 | I19: =XLostxDestinyX!$F$10 | L19: ='Sunshine Warrior'!$F$10 | O19: =YLO!$F$10 | R19: =Saturnalia!$F$10
C20: Springacres | F20: Pinkshadow | I20: XLostxDestinyX | L20: Sunshine Warrior | O20: YLO | R20: Saturnalia
C21: =IMAGE(Cats!$F$5, 3) | D21: =IMAGE(Hats!$G$27, 3) | F21: =IMAGE(Cats!$F$2, 3) | G21: =IMAGE(Hats!$G$3, 3) | I21: =IMAGE(Cats!$F$3, 3) | J21: =IMAGE(Hats!$G$31, 3) | L21: =IMAGE(Cats!$F$5, 3) | M21: =IMAGE(Hats!$G$26, 3) | O21: =IMAGE(Cats!$F$2, 3) | R21: =IMAGE(Cats!$F$4, 3)
C23: =Ember!$F$10 | F23: ='Luv007'!$F$10 | I23: =Wildfilly94!$F$10 | L23: =Aralie!$F$10 | O23: =Ryuukokoro!$F$10 | R23: =SeaCrest!$F$10
C24: Ember | F24: Luv007 | I24: Wildfilly94 | L24: Aralie | O24: Ryuukokoro | R24: SeaCrest
C25: =IMAGE(Cats!$F$4, 3) | F25: =IMAGE(Cats!$F$3, 3) | G25: =IMAGE(Hats!$G$34, 3) | I25: =IMAGE(Cats!$F$3, 3) | J25: =IMAGE(Hats!$G$24, 3) | L25: =IMAGE(Cats!$F$4, 3) | M25: =IMAGE(Hats!$G$33, 3) | O25: =IMAGE(Cats!$F$2, 3) | P25: =IMAGE(Hats!$G$34, 3) | R25: =IMAGE(Cats!$F$3, 3)

Sheet !WIP! - Shard Shop
C2: Cat Colours
C4: =image(Shop!$F$2, 3) | D4: =Shop!$C$2 -> Tabby, Grey | F4: =image(Shop!$F$3, 3) | G4: =Shop!$C$3 -> Tabby, Brown | I4: =image(Shop!$F$4, 3) | J4: =Shop!$C$4 -> Tabby, Orange | L4: =image(Shop!$F$5, 3) | M4: =Shop!$C$5 -> Tabby, Torbie
D5: =CONCATENATE(Shop!$D$2, " (", Shop!$B$2,")") -> *B01 (Basic) | G5: =CONCATENATE(Shop!$D$3, " (", Shop!$B$3,")") -> *B02 (Basic) | J5: =Shop!$D$4 -> *B03 | M5: =Shop!$D$5 -> *B04
D6: =CONCAT(Shop!$I$2, " 💎") -> 25 💎 | G6: =CONCAT(Shop!$I$3, " 💎") -> 25 💎 | J6: =CONCAT(Shop!$I$4, " 💎") -> 25 💎 | M6: =CONCAT(Shop!$I$5, " 💎") -> 25 💎
D7: =Shop!$E$2 -> Likes to push things off tables. | G7: =Shop!$E$3 -> Will climb anything, people included. | J7: =Shop!$E$4 -> Never stops meowing. | M7: =Shop!$E$5 -> Loves you... when they feel like it!
C9: =image(Shop!$F$6, 3) | D9: =Shop!$C$6 -> Galaxy | F9: =image(Shop!$F$7, 3) | G9: =Shop!$C$7 -> Glass | I9: =image(Shop!$F$8, 3) | J9: =Shop!$C$8 -> Meadow | L9: =image(Shop!$F$9, 3) | M9: =Shop!$C$9 -> Magma
D10: =CONCATENATE(Shop!$D$6, " (", Shop!$B$6,")") -> *C01 (Shop Exclusive) | G10: =Shop!$D$7 -> *C02 | J10: =Shop!$D$8 -> *C03 | M10: =Shop!$D$9 -> *C04
D11: =CONCAT(Shop!$I$6, " 💎") -> 200 💎 | G11: =CONCAT(Shop!$I$7, " 💎") -> 200 💎 | J11: =CONCAT(Shop!$I$9, " 💎") -> 200 💎 | M11: =CONCAT(Shop!$I$9, " 💎") -> 200 💎
D12: =Shop!$E$6 -> Twinkles. | G12: =Shop!$E$7 -> Tinkles. | J12: =Shop!$E$8 -> Smells like fresh grass. | M12: =Shop!$E$9 -> Hot, hot, HOT!

Sheet Aralie
B2: Aralie
J3: Currency | N3: =IFERROR(__xludf.DUMMYFUNCTION("SUM(IFERROR(QUERY(Records!$A:$F, CONCATENATE(""select F where B contains '"", $B2, ""'""), 0))) - SUM(IFERROR(QUERY(Records!$A:$F, CONCATENATE(""select G where B contains '"", $B2, ""'""), 0)))"),101.0) -> 101
J5: =IMAGE("https://i.postimg.cc/nhjVf0b3/aralie-big.pngg", 3)
J6: Sylvie
J7: =IMAGE(Cats!$F$4, 3) | M7: =IMAGE(Hats!$G$33, 3)
B9: Outfits
B10: =IMAGE("https://i.postimg.cc/LshrLMm2/aralie-000.png", 3) | F10: =IMAGE("https://i.postimg.cc/HspQ6CgQ/aralie-001.png", 3) | J10: =IMAGE("https://i.postimg.cc/ZRv9sfy5/aralie-002.png", 3)
B11: =date(2022,3,17) -> 44637 | F11: =date(2022,3,27) -> 44647 | J11: =date(2022, 4, 4) -> 44655
B12: =IMAGE(Cats!$F$4, 3) | C12: =IMAGE(Hats!$G$3, 3) | F12: =IMAGE(Cats!$F$4, 3) | G12: =IMAGE(Hats!$G$33, 3) | J12: =IMAGE(Cats!$F$9, 3) | K12: =IMAGE(Hats!$G$35, 3)
B14: Cat Collection
B15: =IMAGE(Cats!$E$4, 3) | F15: =IMAGE(Cats!$E$9, 3) | J15: =IMAGE(Cats!$E$13, 3)
B16: =Cats!$C$4 -> *A03 | F16: =Cats!$C$9 -> *B04 | J16: =Cats!$C$13 -> *B08
B18: Hat Collection
B19: =IMAGE(Hats!$F$3, 3) | F19: =IMAGE(Hats!$F$8, 3) | J19: =image(Hats!$F$11, 3) | N19: =image(Hats!$F$13, 3) | R19: =IMAGE(Hats!$F$16, 3)
B20: =Hats!$C$3 -> AA02 | C20: 1 | F20: =Hats!$C$8 -> AB03 | G20: 1 | J20: =Hats!$C$11 -> AB06 | K20: 1 | N20: =Hats!$C$13 -> AB08 | O20: 1 | R20: =Hats!$C$16 -> AB11 | S20: 1
B22: =IMAGE(Hats!$F$21, 3) | F22: =IMAGE(Hats!$F$22, 3) | J22: =IMAGE(Hats!$F$24, 3) | N22: =IMAGE(Hats!$F$25, 3) | R22: =IMAGE(Hats!$F$27, 3) | V22: =IMAGE(Hats!$F$29, 3)
B23: =Hats!$C$21 -> AC04 | C23: 1 | F23: =Hats!$C$22 -> AC05 | G23: 1 | J23: =Hats!$C$24 -> AC07 | K23: 1 | N23: =Hats!$C$25 -> AC08 | O23: 1 | R23: =Hats!$C$27 -> AC10 | S23: 2 | V23: =Hats!$C$29 -> AC12 | W23: 1
B25: =IMAGE(Hats!$F$30, 3) | J25: =IMAGE(Hats!$F$32, 3) | N25: =IMAGE(Hats!$F$33, 3) | R25: =IMAGE(Hats!$F$34, 3) | V25: =IMAGE(Hats!$F$35, 3)
B26: =Hats!$C$30 -> AC13 | C26: 2 | F26: AC14 | G26: 1 | J26: =Hats!$C$32 -> AC15 | K26: 1 | N26: =Hats!$C$33 -> AC16 | O26: 1 | R26: =Hats!$C$34 -> AC17 | S26: 1 | V26: =Hats!$C$35 -> AC18 | W26: 1
B28: =IMAGE(Hats!$F$36, 3)
B29: =Hats!$C$36 -> AC19 | C29: 1

Sheet Ember
B2: Ember
J3: Currency | N3: =IFERROR(__xludf.DUMMYFUNCTION("SUM(IFERROR(QUERY(Records!$A:$F, CONCATENATE(""select F where B contains '"", $B2, ""'""), 0))) - SUM(IFERROR(QUERY(Records!$A:$F, CONCATENATE(""select G where B contains '"", $B2, ""'""), 0)))"),18.0) -> 18
J5: =IMAGE("https://i.postimg.cc/R0XYWX6k/ember-big.png", 3)
J6: Niko
J7: =IMAGE(Cats!$F$4, 3) | M7: =IMAGE(Hats!$G$3, 3)
B9: Outfits
B10: =IMAGE("https://i.postimg.cc/FKWrBxyX/ember-000.png", 3) | F10: =IMAGE("https://i.postimg.cc/YqbQVyrT/ember-001.png", 3)
B11: =date(2022,3,17) -> 44637 | F11: =date(2022,3,27) -> 44647
B12: =IMAGE(Cats!$F$4, 3) | C12: =IMAGE(Hats!$G$3, 3) | F12: =IMAGE(Cats!$F$4, 3) | G12: =IMAGE(Hats!$G$31, 3)
B14: Cat Collection
B15: =IMAGE(Cats!$E$4, 3) | F15: =IMAGE(Cats!$E$8, 3)
B16: =Cats!$C$4 -> *A03 | F16: =Cats!$C$8 -> *B03
B18: Hat Collection
B19: =IMAGE(Hats!$F$3, 3) | F19: =IMAGE(Hats!$F$17, 3) | J19: =IMAGE(Hats!$F$19, 3) | N19: =IMAGE(Hats!$F$25, 3) | R19: =IMAGE(Hats!$F$28, 3) | V19: =IMAGE(Hats!$F$29, 3)
B20: =Hats!$C$3 -> AA02 | C20: 1 | F20: =Hats!$C$17 -> AB12 | G20: 1 | J20: =Hats!$C$19 -> AC02 | K20: 1 | N20: =Hats!$C$25 -> AC08 | O20: 1 | R20: =Hats!$C$28 -> AC11 | S20: 1 | V20: =Hats!$C$29 -> AC12 | W20: 1
B22: =IMAGE(Hats!$F$30, 3) | J22: =IMAGE(Hats!$F$33, 3) | N22: =IMAGE(Hats!$F$35, 3)
B23: =Hats!$C$30 -> AC13 | C23: 1 | F23: AC14 | G23: 1 | J23: =Hats!$C$33 -> AC16 | K23: 1 | N23: =Hats!$C$35 -> AC18 | O23: 1

Sheet Luv007
B2: Luv007
J3: Currency | N3: =IFERROR(__xludf.DUMMYFUNCTION("SUM(IFERROR(QUERY(Records!$A:$F, CONCATENATE(""select F where B contains '"", $B2, ""'""), 0))) - SUM(IFERROR(QUERY(Records!$A:$F, CONCATENATE(""select G where B contains '"", $B2, ""'""), 0)))"),88.0) -> 88
J5: =IMAGE("https://i.postimg.cc/ydCXLBz0/luv007-big.png", 3)
J6: Jumanji
J7: =IMAGE(Cats!$F$3, 3) | M7: =IMAGE(Hats!$G$5, 3)
B9: Outfits
B10: =IMAGE("https://i.postimg.cc/wTWZmTdF/luv007-000.png", 3) | F10: =IMAGE("https://i.postimg.cc/dQR2RVzs/luv007-001.png", 3) | J10: =IMAGE("https://i.postimg.cc/QCMzrThC/luv007-002.png", 3)
B11: =date(2022,3,17) -> 44637 | F11: =date(2022,3,27) -> 44647 | J11: =date(2022, 4, 4) -> 44655
C12: =IMAGE(Hats!$G$5, 3) | G12: =IMAGE(Hats!$G$34, 3) | J12: =IMAGE(Cats!$F$9, 3) | K12: =IMAGE(Hats!$G$35, 3)
B14: Cat Collection
B15: =IMAGE(Cats!$E$3, 3) | F15: =IMAGE(Cats!$E$9, 3) | J15: =IMAGE(Cats!$E$10, 3)
B16: =Cats!$C$3 -> *A02 | F16: =Cats!$C$9 -> *B04 | J16: =Cats!$C$10 -> *B05
B18: Hat Collection
B19: =IMAGE(Hats!$F$5, 3) | F19: =IMAGE(Hats!$F$6, 3) | J19: =IMAGE(Hats!$F$7, 3) | N19: =image(Hats!$F$11, 3) | R19: =IMAGE(Hats!$F$13, 3)
B20: =Hats!$C$5 -> AA04 | C20: 1 | F20: =Hats!$C$6 -> AB01 | G20: 1 | J20: =Hats!$C$7 -> AB02 | K20: 1 | N20: =Hats!$C$11 -> AB06 | O20: 1 | R20: =Hats!$C$13 -> AB08 | S20: 1
B22: =IMAGE(Hats!$F$19, 3) | F22: =IMAGE(Hats!$F$20, 3) | J22: =IMAGE(Hats!$F$21, 3) | N22: =IMAGE(Hats!$F$24, 3) | R22: =IMAGE(Hats!$F$26, 3) | V22: =IMAGE(Hats!$F$27, 3)
B23: =Hats!$C$19 -> AC02 | C23: 1 | F23: =Hats!$C$20 -> AC03 | G23: 1 | J23: =Hats!$C$21 -> AC04 | K23: 1 | N23: =Hats!$C$24 -> AC07 | O23: 1 | R23: =Hats!$C$26 -> AC09 | S23: 1 | V23: =Hats!$C$27 -> AC10 | W23: 2
B25: =IMAGE(Hats!$F$30, 3) | F25: =IMAGE(Hats!$F$33, 3) | J25: =IMAGE(Hats!$F$34, 3) | N25: =IMAGE(Hats!$F$35, 3) | R25: =IMAGE(Hats!$F$36, 3)
B26: =Hats!$C$30 -> AC13 | C26: 1 | F26: =Hats!$C$33 -> AC16 | G26: 1 | J26: =Hats!$C$34 -> AC17 | K26: 1 | N26: =Hats!$C$35 -> AC18 | O26: 1 | R26: =Hats!$C$36 -> AC19 | S26: 1
B28: =IMAGE(Hats!$F$38, 3) | F28: =IMAGE(Hats!$F$39, 3)
B29: =Hats!$C$38 -> AD01 | C29: 1 | F29: =Hats!$C$39 -> AD02 | G29: 1

Sheet Pinkshadow
B2: Pinkshadow
J3: Currency | N3: =IFERROR(__xludf.DUMMYFUNCTION("SUM(IFERROR(QUERY(Records!$A:$F, CONCATENATE(""select F where B contains '"", $B2, ""'""), 0))) - SUM(IFERROR(QUERY(Records!$A:$F, CONCATENATE(""select G where B contains '"", $B2, ""'""), 0)))"),83.0) -> 83
J5: =IMAGE("https://i.postimg.cc/3N29FR6M/pinkshadow-big.png", 3)
J6: Sophy
J7: =IMAGE(Cats!$F$2, 3) | M7: =IMAGE(Hats!$G$3, 3)
B9: Outfits
B10: =IMAGE("https://i.postimg.cc/mDN62TwY/pinkshadow-000.png", 3) | F10: =IMAGE("https://i.postimg.cc/YCcJv87B/pinkshadow-001.png", 3) | J10: =IMAGE("https://i.postimg.cc/MKfCZNhY/pinkshadow-002.png", 3)
B11: =date(2022,3,17) -> 44637 | F11: =date(2022,3,27) -> 44647 | J11: =date(2022, 4, 4) -> 44655
B12: =IMAGE(Cats!$F$2, 3) | C12: =IMAGE(Hats!$G$3, 3) | F12: =IMAGE(Cats!$F$2, 3) | G12: =IMAGE(Hats!$G$3, 3) | J12: =IMAGE(Cats!$F$9, 3) | K12: =IMAGE(Hats!$G$7, 3)
B14: Cat Collection
B15: =IMAGE(Cats!$E$2, 3) | F15: =IMAGE(Cats!$E$8, 3) | J15: =IMAGE(Cats!$E$9, 3) | N15: =IMAGE(Cats!$E$10, 3)
B16: =Cats!$C$2 -> *A01 | F16: =Cats!$C$8 -> *B03 | J16: =Cats!$C$9 -> *B04 | N16: =Cats!$C$10 -> *B05
B18: Hat Collection
B19: =IMAGE(Hats!$F$3, 3) | F19: =IMAGE(Hats!$F$6, 3) | J19: =IMAGE(Hats!$F$7, 3) | N19: =IMAGE(Hats!$F$9, 3) | R19: =image(Hats!$F$10, 3) | V19: =image(Hats!$F$11, 3)
B20: =Hats!$C$3 -> AA02 | C20: 1 | F20: =Hats!$C$6 -> AB01 | G20: 1 | J20: =Hats!$C$7 -> AB02 | K20: 1 | N20: =Hats!$C$9 -> AB04 | O20: 1 | R20: =Hats!$C$10 -> AB05 | S20: 1 | V20: =Hats!$C$11 -> AB06 | W20: 1
B22: =IMAGE(Hats!$F$12, 3) | F22: =image(Hats!$F$13, 3) | J22: =IMAGE(Hats!$F$16, 3) | N22: =IMAGE(Hats!$F$17, 3)
B23: =Hats!$C$12 -> AB07 | C23: 1 | F23: =Hats!$C$13 -> AB08 | G23: 1 | J23: =Hats!$C$16 -> AB11 | K23: 1 | N23: =Hats!$C$17 -> AB12 | O23: 1
B25: =image(Hats!$F$18, 3) | F25: =IMAGE(Hats!$F$21, 3) | J25: =IMAGE(Hats!$F$22, 3) | N25: =IMAGE(Hats!$F$30, 3) | R25: =IMAGE(Hats!$F$32, 3)
B26: =Hats!$C$18 -> AC01 | C26: 1 | F26: =Hats!$C$21 -> AC04 | G26: 1 | J26: =Hats!$C$22 -> AC05 | K26: 1 | N26: =Hats!$C$30 -> AC13 | O26: 1 | R26: =Hats!$C$32 -> AC15 | S26: 1

Sheet Ryuukokoro
B2: Ryuukokoro
J3: Currency | N3: =IFERROR(__xludf.DUMMYFUNCTION("SUM(IFERROR(QUERY(Records!$A:$F, CONCATENATE(""select F where B contains '"", $B2, ""'""), 0))) - SUM(IFERROR(QUERY(Records!$A:$F, CONCATENATE(""select G where B contains '"", $B2, ""'""), 0)))"),140.0) -> 140
J5: =IMAGE("https://i.postimg.cc/02R56nPc/ryuukokoro-big.png", 3)
J6: Magic
J7: =IMAGE(Cats!$F$2, 3) | M7: =IMAGE(Hats!$G$3, 3)
B9: Outfits
B10: =IMAGE("https://i.postimg.cc/D0vpSRjt/ryuukokoro-000.png", 3) | F10: =IMAGE("https://i.postimg.cc/wjnR8CS4/ryuukokoro-001.png", 3) | J10: =IMAGE("https://i.postimg.cc/mDwmgNwR/ryuukokoro-002.png", 3)
B11: =date(2022,3,19) -> 44639 | F11: =date(2022,3,27) -> 44647 | J11: =date(2022, 4, 4) -> 44655
B12: =IMAGE(Cats!$F$2, 3) | C12: =IMAGE(Hats!$G$3, 3) | F12: =IMAGE(Cats!$F$2, 3) | G12: =IMAGE(Hats!$G$34, 3) | J12: =IMAGE(Cats!$F$2, 3) | K12: =IMAGE(Hats!$G$35, 3)
B14: Cat Collection
B15: =IMAGE(Cats!$E$2, 3) | F15: =IMAGE(Cats!$E$6, 3) | J15: =IMAGE(Cats!$E$8, 3) | N15: =IMAGE(Cats!$E$13, 3)
B16: =Cats!$C$2 -> *A01 | F16: =Cats!$C$6 -> *B01 | J16: =Cats!$C$8 -> *B03 | N16: =Cats!$C$13 -> *B08
B18: Hat Collection
B19: =IMAGE(Hats!$F$3, 3) | F19: =IMAGE(Hats!$F$6, 3) | J19: =IMAGE(Hats!$F$7, 3) | N19: =IMAGE(Hats!$F$8, 3) | R19: =IMAGE(Hats!$F$9, 3) | V19: =image(Hats!$F$10, 3)
B20: =Hats!$C$3 -> AA02 | C20: 1 | F20: =Hats!$C$6 -> AB01 | G20: 1 | J20: =Hats!$C$7 -> AB02 | K20: 1 | N20: =Hats!$C$8 -> AB03 | O20: 1 | R20: =Hats!$C$9 -> AB04 | S20: 1 | V20: =Hats!$C$10 -> AB05 | W20: 1
B22: =IMAGE(Hats!$F$16, 3) | F22: =IMAGE(Hats!$F$17, 3)
B23: =Hats!$C$16 -> AB11 | C23: 1 | F23: =Hats!$C$17 -> AB12 | G23: 1
B25: =IMAGE(Hats!$F$19, 3) | F25: =IMAGE(Hats!$F$20, 3) | J25: =IMAGE(Hats!$F$24, 3) | N25: =IMAGE(Hats!$F$25, 3) | R25: =IMAGE(Hats!$F$26, 3) | V25: =IMAGE(Hats!$F$27, 3)
B26: =Hats!$C$19 -> AC02 | C26: 1 | F26: =Hats!$C$20 -> AC03 | G26: 1 | J26: =Hats!$C$24 -> AC07 | K26: 1 | N26: =Hats!$C$25 -> AC08 | O26: 1 | R26: =Hats!$C$26 -> AC09 | S26: 1 | V26: =Hats!$C$27 -> AC10 | W26: 1
F28: =IMAGE(Hats!$F$32, 3) | J28: =IMAGE(Hats!$F$33, 3) | N28: =IMAGE(Hats!$F$34, 3) | R28: =IMAGE(Hats!$F$35, 3) | V28: =IMAGE(Hats!$F$36, 3)
B29: AC14 | C29: 1 | F29: =Hats!$C$32 -> AC15 | G29: 1 | J29: =Hats!$C$33 -> AC16 | K29: 1 | N29: =Hats!$C$34 -> AC17 | O29: 1 | R29: =Hats!$C$35 -> AC18 | S29: 1 | V29: =Hats!$C$36 -> AC19 | W29: 1
B31: =IMAGE(Hats!$F$38, 3) | F31: =IMAGE(Hats!$F$39, 3)
B32: =Hats!$C$38 -> AD01 | C32: 1 | F32: =Hats!$C$39 -> AD02 | G32: 1

Sheet Saturnalia
B2: Saturnalia
J3: Currency | N3: =IFERROR(__xludf.DUMMYFUNCTION("SUM(IFERROR(QUERY(Records!$A:$F, CONCATENATE(""select F where B contains '"", $B2, ""'""), 0))) - SUM(IFERROR(QUERY(Records!$A:$F, CONCATENATE(""select G where B contains '"", $B2, ""'""), 0)))"),85.0) -> 85
J5: =IMAGE("https://i.postimg.cc/T3nfFMLT/saturnalia-big.png", 3)
J6: Puff
J7: =IMAGE(Cats!$F$4, 3) | M7: =IMAGE(Hats!$G$4, 3)
B9: Outfits
B10: =IMAGE("https://i.postimg.cc/BvFVkTPw/saturnalia-000.png", 3) | F10: =IMAGE("https://i.postimg.cc/9fTRWx2m/saturnalia-001.png", 3) | J10: =IMAGE("https://i.postimg.cc/dQ8pZr5b/saturnalia-002.png", 3)
B11: =date(2022,3,17) -> 44637 | F11: =date(2022,3,27) -> 44647 | J11: =date(2022, 4, 4) -> 44655
B12: =IMAGE(Cats!$F$4, 3) | C12: =IMAGE(Hats!$G$4, 3) | F12: =IMAGE(Cats!$F$4, 3) | G12: =IMAGE(Hats!$G$11, 3) | J12: =IMAGE(Cats!$F$4, 3) | K12: =IMAGE(Hats!$G$38, 3)
B14: Cat Collection
B15: =IMAGE(Cats!$E$4, 3) | F15: =IMAGE(Cats!$E$7, 3) | J15: =IMAGE(Cats!$E$9, 3) | N15: =IMAGE(Cats!$E$12, 3)
B16: =Cats!$C$4 -> *A03 | F16: =Cats!$C$7 -> *B02 | J16: =Cats!$C$9 -> *B04 | N16: =Cats!$C$12 -> *B07
B18: Hat Collection
B19: =IMAGE(Hats!$F$4, 3)
B20: =Hats!$C$4 -> AA03 | C20: 1
B22: =IMAGE(Hats!$F$6, 3) | F22: =IMAGE(Hats!$F$8, 3) | J22: =IMAGE(Hats!$F$9, 3) | N22: =image(Hats!$F$10, 3) | R22: =image(Hats!$F$11, 3) | V22: =IMAGE(Hats!$F$12, 3)
B23: =Hats!$C$6 -> AB01 | C23: 1 | F23: =Hats!$C$8 -> AB03 | G23: 1 | J23: =Hats!$C$9 -> AB04 | K23: 1 | N23: =Hats!$C$10 -> AB05 | O23: 1 | R23: =Hats!$C$11 -> AB06 | S23: 2 | V23: =Hats!$C$12 -> AB07 | W23: 1
B25: =IMAGE(Hats!$F$13, 3) | F25: =IMAGE(Hats!$F$14, 3) | J25: =IMAGE(Hats!$F$15, 3) | N25: =IMAGE(Hats!$F$17, 3)
B26: =Hats!$C$13 -> AB08 | C26: 1 | F26: =Hats!$C$14 -> AB09 | G26: 1 | J26: =Hats!$C$15 -> AB10 | K26: 1 | N26: =Hats!$C$17 -> AB12 | O26: 1
B28: =image(Hats!$F$18, 3) | F28: =IMAGE(Hats!$F$20, 3) | J28: =IMAGE(Hats!$F$22, 3) | N28: =IMAGE(Hats!$F$26, 3) | R28: =IMAGE(Hats!$F$29, 3) | V28: =IMAGE(Hats!$F$30, 3)
B29: =Hats!$C$18 -> AC01 | C29: 2 | F29: =Hats!$C$20 -> AC03 | G29: 1 | J29: =Hats!$C$22 -> AC05 | K29: 2 | N29: =Hats!$C$26 -> AC09 | O29: 1 | R29: =Hats!$C$29 -> AC12 | S29: 1 | V29: =Hats!$C$30 -> AC13 | W29: 1
B31: =IMAGE(Hats!$F$32, 3)
B32: =Hats!$C$32 -> AC15 | C32: 1
B34: =IMAGE(Hats!$F$38, 3) | F34: =IMAGE(Hats!$F$39, 3)
B35: =Hats!$C$38 -> AD01 | C35: 1 | F35: =Hats!$C$39 -> AD02 | G35: 1

Sheet SeaCrest
B2: SeaCrest
J3: Currency | N3: =IFERROR(__xludf.DUMMYFUNCTION("SUM(IFERROR(QUERY(Records!$A:$F, CONCATENATE(""select F where B contains '"", $B2, ""'""), 0))) - SUM(IFERROR(QUERY(Records!$A:$F, CONCATENATE(""select G where B contains '"", $B2, ""'""), 0)))"),137.0) -> 137
J5: =IMAGE("https://i.postimg.cc/4x2rc4ps/seacrest-big.png", 3)
J6: Nia
J7: =IMAGE(Cats!$F$3, 3) | M7: =IMAGE(Hats!$G$3, 3)
B9: Outfits
B10: =IMAGE("https://i.postimg.cc/cL2zF9Cn/seacrest-000.png", 3) | F10: =IMAGE("https://i.postimg.cc/hjBJh949/seacrest-001.png", 3) | J10: =IMAGE("https://i.postimg.cc/1tBQ6dSj/seacrest-002.png", 3)
B11: =date(2022,3,17) -> 44637 | F11: =date(2022,3,27) -> 44647 | J11: =date(2022, 4, 3) -> 44654
B12: =IMAGE(Cats!$F$3, 3) | C12: =IMAGE(Hats!$G$3, 3) | F12: =IMAGE(Cats!$F$3, 3) | G12: =IMAGE(Hats!$G$29, 3) | J12: =IMAGE(Cats!$F$6, 3) | K12: =IMAGE(Hats!$G$11, 3)
B14: Cat Collection
B15: =IMAGE(Cats!$E$3, 3) | F15: =IMAGE(Cats!$E$6, 3) | J15: =IMAGE(Cats!$E$13, 3) | N15: =image(Cats!$E$17, 3)
B16: =Cats!$C$3 -> *A02 | F16: =Cats!$C$6 -> *B01 | J16: =Cats!$C$13 -> *B08 | N16: =Cats!$C$17 -> *B12
B18: Hat Collection
B19: =IMAGE(Hats!$F$3, 3) | F19: =IMAGE(Hats!$F$6, 3) | J19: =IMAGE(Hats!$F$9, 3) | N19: =image(Hats!$F$10, 3) | R19: =IMAGE(Hats!$F$11, 3) | V19: =IMAGE(Hats!$F$12, 3)
B20: =Hats!$C$3 -> AA02 | C20: 1 | F20: =Hats!$C$6 -> AB01 | G20: 1 | J20: =Hats!$C$9 -> AB04 | K20: 1 | N20: =Hats!$C$10 -> AB05 | O20: 1 | R20: =Hats!$C$11 -> AB06 | S20: 1 | V20: =Hats!$C$12 -> AB07 | W20: 2
B22: =IMAGE(Hats!$F$13, 3)
B23: =Hats!$C$13 -> AB08 | C23: 1
B25: =IMAGE(Hats!$F$19, 3) | F25: =IMAGE(Hats!$F$20, 3) | J25: =IMAGE(Hats!$F$23, 3) | N25: =IMAGE(Hats!$F$24, 3) | R25: =IMAGE(Hats!$F$25, 3) | V25: =IMAGE(Hats!$F$26, 3)
B26: =Hats!$C$19 -> AC02 | C26: 1 | F26: =Hats!$C$20 -> AC03 | G26: 1 | J26: =Hats!$C$23 -> AC06 | K26: 1 | N26: =Hats!$C$24 -> AC07 | O26: 1 | R26: =Hats!$C$25 -> AC08 | S26: 1 | V26: =Hats!$C$26 -> AC09 | W26: 1
B28: =IMAGE(Hats!$F$27, 3) | F28: =IMAGE(Hats!$F$28, 3) | J28: =IMAGE(Hats!$F$29, 3) | N28: =IMAGE(Hats!$F$30, 3) | R28: =IMAGE(Hats!$F$31, 3) | V28: =IMAGE(Hats!$F$36, 3)
B29: =Hats!$C$27 -> AC10 | C29: 2 | F29: =Hats!$C$28 -> AC11 | G29: 1 | J29: =Hats!$C$29 -> AC12 | K29: 2 | N29: =Hats!$C$30 -> AC13 | O29: 1 | R29: =Hats!$C$31 -> AC14 | S29: 1 | V29: =Hats!$C$36 -> AC19 | W29: 1
B31: =IMAGE(Hats!$F$38, 3) | F31: =IMAGE(Hats!$F$39, 3)
B32: =Hats!$C$38 -> AD01 | C32: 1 | F32: =Hats!$C$39 -> AD02 | G32: 1

Sheet Silvanon
B2: Silvanon
J3: Currency | N3: =IFERROR(__xludf.DUMMYFUNCTION("SUM(IFERROR(QUERY(Records!$A:$F, CONCATENATE(""select F where B contains '"", $B2, ""'""), 0))) - SUM(IFERROR(QUERY(Records!$A:$F, CONCATENATE(""select G where B contains '"", $B2, ""'""), 0)))"),26.0) -> 26
J5: =IMAGE("https://i.postimg.cc/ZKKVdTcQ/silvanon-big.png", 3)
J6: Grant
J7: =IMAGE(Cats!$F$4, 3) | M7: =IMAGE(Hats!$G$5, 3)
B9: Cat Collection
B10: =IMAGE(Cats!$E$4, 3)
B12: Hat Collection
B13: =IMAGE(Hats!$F$5, 3) | F13: =IMAGE(Hats!$F$9, 3) | J13: =image(Hats!$F$10, 3) | N13: =IMAGE(Hats!$F$11, 3) | R13: =IMAGE(Hats!$F$17, 3)
B14: =Hats!$C$5 -> AA04 | C14: 1 | F14: =Hats!$C$9 -> AB04 | G14: 1 | J14: =Hats!$C$10 -> AB05 | K14: 1 | N14: =Hats!$C$11 -> AB06 | O14: 1 | R14: =Hats!$C$17 -> AB12 | S14: 1
B16: =image(Hats!$F$18, 3) | F16: =IMAGE(Hats!$F$29, 3) | J16: =IMAGE(Hats!$F$32, 3)
B17: =Hats!$C$18 -> AC01 | C17: 1 | F17: =Hats!$C$29 -> AC12 | G17: 1 | J17: =Hats!$C$32 -> AC15 | K17: 1

Sheet Springacres
B2: Springacres
J3: Currency | N3: =IFERROR(__xludf.DUMMYFUNCTION("SUM(IFERROR(QUERY(Records!$A:$F, CONCATENATE(""select F where B contains '"", $B2, ""'""), 0))) - SUM(IFERROR(QUERY(Records!$A:$F, CONCATENATE(""select G where B contains '"", $B2, ""'""), 0)))"),30.0) -> 30
J5: =IMAGE("https://i.postimg.cc/kMsh0XD9/springacres-big.png", 3)
J6: Copurrnicus
J7: =IMAGE(Cats!$F$5, 3) | M7: =IMAGE(Hats!$G$2, 3)
B9: Outfits
B10: =IMAGE("https://i.postimg.cc/X7p9RkrJ/springacres-000.png", 3) | F10: =IMAGE("https://i.postimg.cc/fLDLMD5C/springacres-001.png", 3) | J10: =IMAGE("https://i.postimg.cc/xTkwT8X7/springacres-002.png", 3)
B11: =date(2022,3,17) -> 44637 | F11: =date(2022,3,27) -> 44647 | J11: =date(2022, 4, 3) -> 44654
B12: =IMAGE(Cats!$F$5, 3) | C12: =IMAGE(Hats!$G$2, 3) | F12: =IMAGE(Cats!$F$5, 3) | G12: =IMAGE(Hats!$G$27, 3) | J12: =IMAGE(Cats!$F$9, 3) | K12: =IMAGE(Hats!$G$30, 3)
B14: Cat Collection
B15: =IMAGE(Cats!$E$5, 3) | F15: =IMAGE(Cats!$E$8, 3) | J15: =IMAGE(Cats!$E$9, 3)
B16: =Cats!$C$5 -> *A04 | F16: =Cats!$C$8 -> *B03 | J16: =Cats!$C$9 -> *B04
B18: Hat Collection
B19: =IMAGE(Hats!$F$2, 3) | F19: =IMAGE(Hats!$F$7, 3) | J19: =IMAGE(Hats!$F$9, 3) | N19: =IMAGE(Hats!$F$13, 3) | R19: =IMAGE(Hats!$F$14, 3)
B20: =Hats!$C$2 -> AA01 | C20: 1 | F20: =Hats!$C$7 -> AB02 | G20: 1 | J20: =Hats!$C$9 -> AB04 | K20: 1 | N20: =Hats!$C$13 -> AB08 | O20: 1 | R20: =Hats!$C$14 -> AB09 | S20: 1
B22: =IMAGE(Hats!$F$19, 3) | F22: =IMAGE(Hats!$F$20, 3) | J22: =IMAGE(Hats!$F$21, 3) | N22: =IMAGE(Hats!$F$25, 3) | R22: =IMAGE(Hats!$F$27, 3) | V22: =IMAGE(Hats!$F$29, 3)
B23: =Hats!$C$19 -> AC02 | C23: 1 | F23: =Hats!$C$20 -> AC03 | G23: 1 | J23: =Hats!$C$21 -> AC04 | K23: 1 | N23: =Hats!$C$25 -> AC08 | O23: 1 | R23: =Hats!$C$27 -> AC10 | S23: 2 | V23: =Hats!$C$29 -> AC12 | W23: 1
B25: =IMAGE(Hats!$F$30, 3)
B26: =Hats!$C$30 -> AC13 | C26: 1
B28: =IMAGE(Hats!$F$38, 3) | F28: =IMAGE(Hats!$F$39, 3)
B29: =Hats!$C$38 -> AD01 | C29: 1 | F29: =Hats!$C$39 -> AD02 | G29: 1

Sheet Laviee
B2: Laviee
J3: Currency | N3: =IFERROR(__xludf.DUMMYFUNCTION("SUM(IFERROR(QUERY(Records!$A:$F, CONCATENATE(""select F where B contains '"", $B2, ""' and E = '+'""), 0))) - SUM(IFERROR(QUERY(Records!$A:$F, CONCATENATE(""select F where B contains '"", $B2, ""' and E = '-'""), 0)))"),0.0) -> 0
J5: =IMAGE("https://i.postimg.cc/3R08Xr3g/laviee-big.png", 3)
J6: Noodle
J7: =IMAGE(Cats!$F$2, 3) | M7: =IMAGE(Hats!$G$27, 3)
B9: Cat Collection
B10: =IMAGE(Cats!$E$2, 3)
B12: Hat Collection
B13: =IMAGE(Hats!$F$27, 3)
B14: =Hats!$C$27 -> AC10 | C14: 1

Sheet Sunshine Warrior
B2: Sunshine Warrior
J3: Currency | N3: =IFERROR(__xludf.DUMMYFUNCTION("SUM(IFERROR(QUERY(Records!$A:$F, CONCATENATE(""select F where B contains '"", $B2, ""'""), 0))) - SUM(IFERROR(QUERY(Records!$A:$F, CONCATENATE(""select G where B contains '"", $B2, ""'""), 0)))"),18.0) -> 18
J5: =IMAGE("https://i.postimg.cc/rwPj8DLX/sunshinewarrior-big.png", 3)
J6: Pam
J7: =IMAGE(Cats!$F$3, 3) | M7: =IMAGE(Hats!$G$3, 3)
B9: Outfits
B10: =IMAGE("https://i.postimg.cc/9Q9ZMXtH/sunshinewarrior-000.png", 3) | F10: =IMAGE("https://i.postimg.cc/W3843CHv/sunshinewarrior-001.png", 3)
B11: =date(2022,3,17) -> 44637 | F11: =date(2022,3,27) -> 44647
B12: =IMAGE(Cats!$F$3, 3) | C12: =IMAGE(Hats!$G$3, 3) | F12: =IMAGE(Cats!$F$3, 3) | G12: =IMAGE(Hats!$G$26, 3)
B14: Cat Collection
B15: =IMAGE(Cats!$E$3, 3) | F15: =IMAGE(Cats!$E$8, 3)
B16: =Cats!$C$3 -> *A02 | F16: =Cats!$C$8 -> *B03
B18: Hat Collection
B19: =IMAGE(Hats!$F$3, 3) | F19: =IMAGE(Hats!$F$7, 3) | J19: =IMAGE(Hats!$F$11, 3) | N19: =IMAGE(Hats!$F$17, 3)
B20: =Hats!$C$3 -> AA02 | C20: 1 | F20: =Hats!$C$7 -> AB02 | G20: 1 | J20: =Hats!$C$11 -> AB06 | K20: 1 | N20: =Hats!$C$17 -> AB12 | O20: 1
B22: =IMAGE(Hats!$F$19, 3) | F22: =IMAGE(Hats!$F$21, 3) | J22: =IMAGE(Hats!$F$23, 3) | N22: =IMAGE(Hats!$F$26, 3) | R22: =IMAGE(Hats!$F$28, 3) | V22: =IMAGE(Hats!$F$33, 3)
B23: =Hats!$C$19 -> AC02 | C23: 1 | F23: =Hats!$C$21 -> AC04 | G23: 1 | J23: =Hats!$C$23 -> AC06 | K23: 1 | N23: =Hats!$C$26 -> AC09 | O23: 1 | R23: =Hats!$C$28 -> AC11 | S23: 1 | V23: =Hats!$C$33 -> AC16 | W23: 1

Sheet Wildfilly94
B2: Wildfilly94
J3: Currency | N3: =IFERROR(__xludf.DUMMYFUNCTION("SUM(IFERROR(QUERY(Records!$A:$F, CONCATENATE(""select F where B contains '"", $B2, ""'""), 0))) - SUM(IFERROR(QUERY(Records!$A:$F, CONCATENATE(""select G where B contains '"", $B2, ""'""), 0)))"),17.0) -> 17
J5: =IMAGE("https://i.postimg.cc/R0t74GRK/wildfilly94-big.png", 3)
J6: Edward
J7: =IMAGE(Cats!$F$3, 3) | M7: =IMAGE(Hats!$G$5, 3)
B9: Outfits
B10: =IMAGE("https://i.postimg.cc/sDq5sGWJ/wildfilly94-000.png", 3) | F10: =IMAGE("https://i.postimg.cc/N0hFP1HW/wildfilly94-001.png", 3)
B11: =date(2022,3,17) -> 44637 | F11: =date(2022,3,27) -> 44647
B12: =IMAGE(Cats!$F$3, 3) | C12: =IMAGE(Hats!$G$5, 3) | F12: =IMAGE(Cats!$F$3, 3) | G12: =IMAGE(Hats!$G$24, 3)
B14: Cat Collection
B15: =IMAGE(Cats!$E$3, 3) | F15: =IMAGE(Cats!$E$8, 3)
B16: =Cats!$C$3 -> *A02 | F16: =Cats!$C$8 -> *B03
B18: Hat Collection
B19: =IMAGE(Hats!$F$5, 3) | F19: =IMAGE(Hats!$F$13, 3) | J19: =IMAGE(Hats!$F$15, 3) | N19: =IMAGE(Hats!$F$19, 3) | R19: =IMAGE(Hats!$F$20, 3) | V19: =IMAGE(Hats!$F$24, 3)
B20: =Hats!$C$5 -> AA04 | C20: 1 | F20: =Hats!$C$13 -> AB08 | G20: 1 | J20: =Hats!$C$15 -> AB10 | K20: 1 | N20: =Hats!$C$19 -> AC02 | O20: 1 | R20: =Hats!$C$20 -> AC03 | S20: 1 | V20: =Hats!$C$24 -> AC07 | W20: 1
B22: =IMAGE(Hats!$F$30, 3)
B23: =Hats!$C$30 -> AC13 | C23: 1

Sheet XLostxDestinyX
B2: XLostxDestinyX
J3: Currency | N3: =IFERROR(__xludf.DUMMYFUNCTION("SUM(IFERROR(QUERY(Records!$A:$F, CONCATENATE(""select F where B contains '"", $B2, ""'""), 0))) - SUM(IFERROR(QUERY(Records!$A:$F, CONCATENATE(""select G where B contains '"", $B2, ""'""), 0)))"),90.0) -> 90
J5: =IMAGE("https://i.postimg.cc/85WkWQcR/xlostxdestinyx-big.png", 3)
J6: Belle
J7: =IMAGE(Cats!$F$3, 3) | M7: =IMAGE(Hats!$G$3, 3)
B9: Outfits
B10: =IMAGE("https://i.postimg.cc/Y0VWgW2Q/xlostxdestinyx-000.png", 3) | F10: =IMAGE("https://i.postimg.cc/Wbz6PXHG/xlostxdestinyx-001.png", 3) | J10: =IMAGE("https://i.postimg.cc/mD5m03yr/xlostxdestinyx-002.png", 3)
B11: =date(2022,3,17) -> 44637 | F11: =date(2022,3,27) -> 44647 | J11: =date(2022, 4, 4) -> 44655
B12: =IMAGE(Cats!$F$3, 3) | C12: =IMAGE(Hats!$G$3, 3) | F12: =IMAGE(Cats!$F$3, 3) | G12: =IMAGE(Hats!$G$31, 3) | J12: =IMAGE(Cats!$F$9, 3) | K12: =IMAGE(Hats!$G$33, 3)
B14: Cat Collection
B15: =IMAGE(Cats!$E$3, 3) | F15: =IMAGE(Cats!$E$9, 3) | J15: =IMAGE(Cats!$E$13, 3)
B16: =Cats!$C$3 -> *A02 | F16: =Cats!$C$9 -> *B04 | J16: =Cats!$C$13 -> *B08
B18: Hat Collection
B19: =IMAGE(Hats!$F$3, 3) | F19: =IMAGE(Hats!$F$7, 3) | J19: =image(Hats!$F$9, 3) | N19: =image(Hats!$F$10, 3) | R19: =image(Hats!$F$17, 3)
B20: =Hats!$C$3 -> AA02 | C20: 1 | F20: =Hats!$C$7 -> AB02 | G20: 1 | J20: =Hats!$C$9 -> AB04 | K20: 3 | N20: =Hats!$C$10 -> AB05 | O20: 1 | R20: =Hats!$C$17 -> AB12 | S20: 1
B22: =image(Hats!$F$18, 3) | F22: =IMAGE(Hats!$F$20, 3) | J22: =IMAGE(Hats!$F$24, 3) | N22: =IMAGE(Hats!$F$28, 3) | R22: =IMAGE(Hats!$F$30, 3) | V22: =IMAGE(Hats!$F$31, 3)
B23: =Hats!$C$18 -> AC01 | C23: 2 | F23: =Hats!$C$20 -> AC03 | G23: 1 | J23: =Hats!$C$24 -> AC07 | K23: 3 | N23: =Hats!$C$28 -> AC11 | O23: 1 | R23: =Hats!$C$30 -> AC13 | S23: 1 | V23: =Hats!$C$31 -> AC14 | W23: 1
B25: =IMAGE(Hats!$F$32, 3) | F25: =IMAGE(Hats!$F$33, 3) | J25: =IMAGE(Hats!$F$34, 3) | N25: =IMAGE(Hats!$F$36, 3)
B26: =Hats!$C$32 -> AC15 | C26: 1 | F26: =Hats!$C$33 -> AC16 | G26: 1 | J26: =Hats!$C$34 -> AC17 | K26: 1 | N26: =Hats!$C$36 -> AC19 | O26: 1
B28: =IMAGE(Hats!$F$38, 3) | F28: =IMAGE(Hats!$F$39, 3)
B29: =Hats!$C$38 -> AD01 | C29: 1 | F29: =Hats!$C$39 -> AD02 | G29: 1

Sheet YLO
B2: YLO
J3: Currency | N3: =IFERROR(__xludf.DUMMYFUNCTION("SUM(IFERROR(QUERY(Records!$A:$F, CONCATENATE(""select F where B contains '"", $B2, ""'""), 0))) - SUM(IFERROR(QUERY(Records!$A:$F, CONCATENATE(""select G where B contains '"", $B2, ""'""), 0)))"),139.0) -> 139
J5: =IMAGE("https://i.postimg.cc/DzhdRwKv/ylo-big.png", 3)
J6: Adriaan
J7: =IMAGE(Cats!$F$2, 3) | M7: =IMAGE(Hats!$G$4, 3)
B9: Outfits
B10: =IMAGE("https://i.postimg.cc/TPXmW8CL/ylo-000.png", 3) | F10: =IMAGE("https://i.postimg.cc/FKjzt7b1/ylo-001.png", 3) | J10: =IMAGE("https://i.postimg.cc/6QkTVSjR/ylo-002.png", 3)
B11: =date(2022,3,17) -> 44637 | F11: =date(2022,3,27) -> 44647 | J11: =date(2022, 4, 4) -> 44655
B12: =IMAGE(Cats!$F$2, 3) | C12: =IMAGE(Hats!$G$4, 3) | F12: =IMAGE(Cats!$F$2, 3) | G12: =IMAGE(Hats!$G$23, 3) | J12: =IMAGE(Cats!$F$7, 3) | K12: =IMAGE(Hats!$G$10, 3)
B14: Cat Collection
B15: =IMAGE(Cats!$E$2, 3) | F15: =IMAGE(Cats!$E$7, 3) | J15: =IMAGE(Cats!$E$11, 3) | N15: =image(Cats!$E$14, 3)
B16: =Cats!$C$2 -> *A01 | F16: =Cats!$C$7 -> *B02 | J16: =Cats!$C$11 -> *B06 | N16: =Cats!$C$14 -> *B09
B18: Hat Collection
B19: =IMAGE(Hats!$F$4, 3) | F19: =IMAGE(Hats!$F$6, 3) | J19: =IMAGE(Hats!$F$8, 3) | N19: =IMAGE(Hats!$F$9, 3) | R19: =image(Hats!$F$10, 3) | V19: =image(Hats!$F$11, 3)
B20: =Hats!$C$4 -> AA03 | C20: 1 | F20: =Hats!$C$6 -> AB01 | G20: 1 | J20: =Hats!$C$8 -> AB03 | K20: 1 | N20: =Hats!$C$9 -> AB04 | O20: 1 | R20: =Hats!$C$10 -> AB05 | S20: 2 | V20: =Hats!$C$11 -> AB06 | W20: 1
B22: =IMAGE(Hats!$F$13, 3)
B23: =Hats!$C$13 -> AB08 | C23: 1
B25: =IMAGE(Hats!$F$20, 3) | F25: =IMAGE(Hats!$F$22, 3) | J25: =IMAGE(Hats!$F$23, 3) | N25: =IMAGE(Hats!$F$24, 3) | R25: =IMAGE(Hats!$F$25, 3) | V25: =IMAGE(Hats!$F$27, 3)
B26: =Hats!$C$20 -> AC03 | C26: 1 | F26: =Hats!$C$22 -> AC05 | G26: 1 | J26: =Hats!$C$23 -> AC06 | K26: 1 | N26: =Hats!$C$24 -> AC07 | O26: 1 | R26: =Hats!$C$25 -> AC08 | S26: 2 | V26: =Hats!$C$27 -> AC10 | W26: 2
B28: =IMAGE(Hats!$F$28, 3) | F28: =IMAGE(Hats!$F$30, 3) | N28: =IMAGE(Hats!$F$35, 3) | R28: =IMAGE(Hats!$F$36, 3)
B29: =Hats!$C$28 -> AC11 | C29: 1 | F29: =Hats!$C$30 -> AC13 | G29: 1 | J29: AC14 | K29: 1 | N29: =Hats!$C$35 -> AC18 | O29: 1 | R29: =Hats!$C$36 -> AC19 | S29: 1
B31: =IMAGE(Hats!$F$38, 3) | F31: =IMAGE(Hats!$F$39, 3)
B32: =Hats!$C$38 -> AD01 | C32: 1 | F32: =Hats!$C$39 -> AD02 | G32: 1

Sheet Records
A1: Date | B1: User | C1: Source | D1: Item + | E1: Items - | F1: Shards + | G1: Shards -
A2: =date(2022,3,17) -> 44637 | B2: Pinkshadow | C2: Starter | D2: AA02
A3: =date(2022,3,17) -> 44637 | B3: Pinkshadow | C3: Starter | D3: *A01
A4: =date(2022,3,17) -> 44637 | B4: Silvanon | C4: Starter | D4: AA04
A5: =date(2022,3,17) -> 44637 | B5: Silvanon | C5: Starter | D5: *A03
A6: =date(2022,3,17) -> 44637 | B6: Luv007 | C6: Starter | D6: AA04
A7: =date(2022,3,17) -> 44637 | B7: Luv007 | C7: Starter | D7: *A02
A8: =date(2022,3,17) -> 44637 | B8: XLostxDestinyX | C8: Starter | D8: AA02
A9: =date(2022,3,17) -> 44637 | B9: XLostxDestinyX | C9: Starter | D9: *A02
A10: =date(2022,3,17) -> 44637 | B10: Saturnalia | C10: Starter | D10: AA03
A11: =date(2022,3,17) -> 44637 | B11: Saturnalia | C11: Starter | D11: *A03
A12: =date(2022,3,17) -> 44637 | B12: SeaCrest | C12: Starter | D12: AA02
A13: =date(2022,3,17) -> 44637 | B13: SeaCrest | C13: Starter | D13: *A02
... A16: =date(2022,3,17) -> 44637 | B16: Saturnalia | C16: Mystery | D16: AB01
A17: =date(2022,3,17) -> 44637 | B17: Ember | C17: Mystery | D17: AC02 | F17: 1
A18: =date(2022,3,17) -> 44637 | B18: XLostxDestinyX | C18: Mystery | D18: AC16 | F18: 1
A19: =date(2022,3,17) -> 44637 | B19: SeaCrest | C19: Mystery | D19: AC14
A20: =date(2022,3,17) -> 44637 | B20: Aralie | C20: Mystery | D20: AC13
A21: =date(2022,3,17) -> 44637 | B21: Pinkshadow | C21: Mystery | D21: AC15 | F21: 1
A22: =date(2022,3,17) -> 44637 | B22: YLO | C22: Starter | D22: AA03
A23: =date(2022,3,17) -> 44637 | B23: YLO | C23: Starter | D23: *A01
A24: =date(2022,3,17) -> 44637 | B24: YLO | C24: Mystery | D24: AB04 | F24: 1
A25: =date(2022,3,17) -> 44637 | B25: Wildfilly94 | C25: Starter | D25: AA04
A26: =date(2022,3,17) -> 44637 | B26: Wildfilly94 | C26: Starter | D26: *A02
A27: =date(2022,3,17) -> 44637 | B27: Wildfilly94 | C27: Mystery | D27: AC13 | F27: 2
A28: =date(2022,3,17) -> 44637 | B28: Springacres | C28: Starter | D28: AA01
A29: =date(2022,3,17) -> 44637 | B29: Springacres | C29: Starter | D29: *A04
A30: =date(2022,3,17) -> 44637 | B30: Luv007 | C30: Mystery | D30: AC07 | F30: 1
A31: =date(2022,3,17) -> 44637 | B31: Springacres | C31: Mystery | D31: AC03 | F31: 1
A32: =date(2022,3,17) -> 44637 | B32: Silvanon | C32: Mystery | D32: AB04
A33: =date(2022,3,18) -> 44638 | B33: SeaCrest | C33: Mystery | D33: AC12
A34: =date(2022,3,18) -> 44638 | B34: Saturnalia | C34: Mystery | D34: AC09 | F34: 1
A35: =date(2022,3,18) -> 44638 | B35: YLO | C35: Mystery | D35: AB08 | F35: 1
A36: =date(2022,3,18) -> 44638 | B36: Ember | C36: Mystery | D36: AB18 | F36: 2
A37: =date(2022,3,18) -> 44638 | B37: XLostxDestinyX | C37: Mystery | D37: AB01 | F37: 2
A38: =date(2022,3,18) -> 44638 | B38: Pinkshadow | C38: Mystery | D38: AB01
A39: =date(2022,3,18) -> 44638 | B39: Sunshine Warrior | C39: Starter | D39: AA02
A40: =date(2022,3,18) -> 44638 | B40: Sunshine Warrior | C40: Starter | D40: *A02
A41: =date(2022,3,18) -> 44638 | B41: Luv007 | C41: Mystery | D41: AC03 | F41: 1
A42: =date(2022,3,18) -> 44638 | B42: Sunshine Warrior | C42: Mystery | D42: AC16
...

Sheet Hats
A1: Set | B1: Name | C1: ID | D1: Description | E1: Owned By | F1: Hat URL | G1: Icon URL
A2: Starter | B2: Cap, Navy | C2: AA01 | D2: For sun protection or fashion? | F2: https://i.postimg.cc/gc7Zb9rR/cap-navy-m.png | G2: https://i.postimg.cc/qqWhsKWQ/cap-navy-i.png
A3: Starter | B3: Beret, Maroon | C3: AA02 | D3: Oui, Oui. | F3: https://i.postimg.cc/pXRsY6XD/beret-maroon-m.png | G3: https://i.postimg.cc/vHh3PtcC/beret-maroon-i.png
A4: Starter | B4: Bucket Hat, Orange | C4: AA03 | D4: I hear they're hip these days. | F4: https://i.postimg.cc/Cx6J0MCN/buckethat-orange-m.png | G4: https://i.postimg.cc/zGfp4Hhv/buckethat-orange-i.png
A5: Starter | B5: Top Hat, Black | C5: AA04 | D5: No pidgeons included. | F5: https://i.postimg.cc/j2Dnnc3L/tophat-m.png | G5: https://i.postimg.cc/Dybb2CbN/tophat-i.png
A6: Basic | B6: Ribbon, Red | C6: AB01 | D6: A pretty bow for your pretty head. | F6: https://i.postimg.cc/1RKd4TxV/ribbon-red-m.png | G6: https://i.postimg.cc/bNCF9twz/ribbon-red-i.png | J6: 1 | K6: reaches into the box and pulls out......... a Red Ribbon! https://i.postimg.cc/1RKd4TxV/ribbon-red-m.png
A7: Basic | B7: Ribbon, Yellow | C7: AB02 | D7: An accessory for a summer day picnic. | F7: https://i.postimg.cc/x1Xpx1XL/ribbon-yellow-m.png | G7: https://i.postimg.cc/5NNRz317/ribbon-yellow-i.png | J7: 2 | K7: reaches into the box and pulls out......... a Yellow Ribbon! https://i.postimg.cc/x1Xpx1XL/ribbon-yellow-m.png
A8: Basic | B8: Cap, Black | C8: AB03 | F8: https://i.postimg.cc/nzkGG312/cap-black-m.png | G8: https://i.postimg.cc/bwd8HdV4/cap-black-i.png | J8: 3 | K8: reaches into the box and pulls out......... a Black Baseball Cap! https://i.postimg.cc/nzkGG312/cap-black-m.png
A9: Basic | B9: Cap, Red | C9: AB04 | F9: https://i.postimg.cc/kGgF1W1m/cap-redwhite-m.png | G9: https://i.postimg.cc/jdxR2MHx/cap-redwhite-i.png | J9: 4 | K9: reaches into the box and pulls out......... a Red Baseball Cap! https://i.postimg.cc/kGgF1W1m/cap-redwhite-m.png
A10: Basic | B10: Party Hat, White | C10: AB05 | F10: https://i.postimg.cc/651zP1x1/partyhat-white-m.png | G10: https://i.postimg.cc/mD1yQ37h/partyhat-white-i.png | J10: 5 | K10: reaches into the box and pulls out......... a White Party Hat! https://i.postimg.cc/651zP1x1/partyhat-white-m.png
A11: Basic | B11: Party Hat, Blue | C11: AB06 | F11: https://i.postimg.cc/hvZ8Hh67/partyhat-blue-m.png | G11: https://i.postimg.cc/3NMC9yZ1/partyhat-blue-i.png | J11: 6 | K11: reaches into the box and pulls out......... a Blue Party Hat! https://i.postimg.cc/hvZ8Hh67/partyhat-blue-m.png
A12: Basic | B12: Party Hat, Green | C12: AB07 | F12: https://i.postimg.cc/B6sCFr2t/partyhat-green-m.png | G12: https://i.postimg.cc/1ztHz1tG/partyhat-green-i.png | J12: 7 | K12: reaches into the box and pulls out......... a Green Party Hat! https://i.postimg.cc/B6sCFr2t/partyhat-green-m.png
A13: Basic | B13: Party Hat, Red | C13: AB08 | F13: https://i.postimg.cc/zGbpYSJD/partyhat-red-m.png | G13: https://i.postimg.cc/VNVFrZr3/partyhat-red-i.png | J13: 8 | K13: reaches into the box and pulls out......... a Red Party Hat! https://i.postimg.cc/zGbpYSJD/partyhat-red-m.png
A14: Basic | B14: Sprout | C14: AB09 | F14: https://i.postimg.cc/wvWt8Jkw/sprout-m.png | G14: https://i.postimg.cc/HLpN4NLn/sprout-i.png | J14: 9 | K14: reaches into the box and pulls out......... a Sprout! https://i.postimg.cc/wvWt8Jkw/sprout-m.png
A15: Basic | B15: Face Mask | C15: AB10 | D15: 6 feet, please! | F15: https://i.postimg.cc/9fDXRSPY/facemask-m.png | G15: https://i.postimg.cc/fbBrHv3K/facemask-i.png | J15: 10 | K15: reaches into the box and pulls out......... a Disposable Face Mask! https://i.postimg.cc/9fDXRSPY/facemask-m.png
A16: Basic | B16: Barrette, Pink | C16: AB11 | F16: https://i.postimg.cc/3w2Bd84P/barette-pink-m.png | J16: 11 | K16: reaches into the box and pulls out......... a Pink Barrette! https://i.postimg.cc/3w2Bd84P/barette-pink-m.png
A17: Basic | B17: Barrette, Purple | C17: AB12 | F17: https://i.postimg.cc/Qd2m89tQ/barette-purple-m.png | J17: 12 | K17: reaches into the box and pulls out......... a Purple Barrette! https://i.postimg.cc/Qd2m89tQ/barette-purple-m.png
A18: Animals | B18: Bunny, Pink | C18: AC01 | D18: Pink and fluffy bunny ears. | F18: https://i.postimg.cc/g01k4Nf8/bunny-m.png | G18: https://i.postimg.cc/xjpwHZdg/bunny-i.png | J18: 13 | K18: reaches into the box and pulls out......... a Pink Bunny Hood! https://i.postimg.cc/g01k4Nf8/bunny-m.png
A19: Animals | B19: Bunny, Pink Bows | C19: AC02 | D19: Pink and fluffy bunny ears. Adorned with little bows. | F19: https://i.postimg.cc/J0L7Ct7h/bunny-bows-m.png | G19: https://i.postimg.cc/3JPzfDmv/bunny-bows-i.png | J19: 14 | K19: reaches into the box and pulls out......... a Pink Bunny Hood with Bows! https://i.postimg.cc/J0L7Ct7h/bunny-bows-m.png
A20: Animals | B20: Bunny, Blue | C20: AC03 | D20: Blue and fluffy bunny ears. | F20: https://i.postimg.cc/C5shhYds/bunny-blue-m.png | G20: https://i.postimg.cc/MKchYYMw/bunny-blue-i.png | J20: 15 | K20: reaches into the box and pulls out......... a Blue Bunny Hood! https://i.postimg.cc/C5shhYds/bunny-blue-m.png
A21: Animals | B21: Bunny, Blue Bows | C21: AC04 | D21: Blue and fluffy bunny ears. Adorned with little bows. | F21: https://i.postimg.cc/FzXV0nX5/bunny-blue-bows-m.png | G21: https://i.postimg.cc/SK5rxxZK/bunny-blue-bows-i.png | J21: 16 | K21: reaches into the box and pulls out......... a Blue Bunny Hood with Bows! https://i.postimg.cc/FzXV0nX5/bunny-blue-bows-m.png
A22: Animals | B22: Froggy, Green | C22: AC05 | D22: Ribbit. | F22: https://i.postimg.cc/jqHdQ6vn/froggy-m.png | G22: https://i.postimg.cc/Pqd30bxP/froggy-i.png | J22: 17 | K22: reaches into the box and pulls out......... a Froggy Hood! https://i.postimg.cc/jqHdQ6vn/froggy-m.png
A23: Animals | B23: Froggy, Toad | C23: AC06 | D23: Croak. | F23: https://i.postimg.cc/2S0Ggwhh/froggy-toad-m.png | G23: https://i.postimg.cc/sfp0qyZx/froggy-toad-i.png | J23: 18 | K23: reaches into the box and pulls out......... a Toad Hood! https://i.postimg.cc/2S0Ggwhh/froggy-toad-m.png
A24: Animals | B24: Froggy, Aqua | C24: AC07 | D24: Is he poisonous? | F24: https://i.postimg.cc/xT9jskFx/froggy-aqua-m.png | G24: https://i.postimg.cc/wjFCPzZL/froggy-aqua-i.png | J24: 19 | K24: reaches into the box and pulls out......... a Aqua Froggy Hood! https://i.postimg.cc/xT9jskFx/froggy-aqua-m.png
A25: Animals | B25: Ducky | C25: AC08 | D25: Cleaning Instructions: Hand wash in a bubble bath. | F25: https://i.postimg.cc/B6DZz20y/ducky-m.png | G25: https://i.postimg.cc/26K0qPxZ/ducky-i.png | J25: 20 | K25: reaches into the box and pulls out......... a Ducky Hood! https://i.postimg.cc/B6DZz20y/ducky-m.png
A26: Animals | B26: Teddy, Brown | C26: AC09 | D26: Soft and cuddly. | F26: https://i.postimg.cc/MGfzc1vT/teddy-m.png | G26: https://i.postimg.cc/9fs7jrn7/teddy-i.png | J26: 21 | K26: reaches into the box and pulls out......... a Teddy Hood! https://i.postimg.cc/MGfzc1vT/teddy-m.png | R26: https://i.postimg.cc/htfgVPDp/teddy-ribbon-i.png
A27: Animals | B27: Teddy, Brown Ribbon | C27: AC10 | D27: 🐻🎀 | F27: https://i.postimg.cc/vHPb16s4/teddy-ribbon-m.png | G27: https://i.postimg.cc/htfgVPDp/teddy-ribbon-i.png | J27: 22 | K27: reaches into the box and pulls out......... a Teddy Hood with Ribbon! https://i.postimg.cc/vHPb16s4/teddy-ribbon-m.png
A28: Animals | B28: Teddy, White | C28: AC11 | D28: Soft and cuddly, but winter themed. | F28: https://i.postimg.cc/hjFcVhd0/teddy-white-m.png | G28: https://i.postimg.cc/x82NcBYj/teddy-white-i.png | J28: 23 | K28: reaches into the box and pulls out......... a White Teddy Hood! https://i.postimg.cc/hjFcVhd0/teddy-white-m.png
A29: Animals | B29: Teddy, White Ribbon | C29: AC12 | D29: 🐻‍❄️🎀 | F29: https://i.postimg.cc/DwMCb70Q/teddy-white-ribbon-m.png | G29: https://i.postimg.cc/Tw8CCQrp/teddy-white-ribbon-i.png | J29: 24 | K29: reaches into the box and pulls out......... a White Teddy Hood with Ribbon! https://i.postimg.cc/DwMCb70Q/teddy-white-ribbon-m.png
A30: Animals | B30: Piggy | C30: AC13 | D30: Smells slightly like maple ham. | F30: https://i.postimg.cc/BQNSRqrq/piggy-m.png | G30: https://i.postimg.cc/vTtg9XHr/piggy-i.png | J30: 25 | K30: reaches into the box and pulls out......... a Piggy Hood! https://i.postimg.cc/BQNSRqrq/piggy-m.png
A31: Animals | B31: Cow | C31: AC14 | D31: Moo. | F31: https://i.postimg.cc/3Rqz5qKJ/cow-m.png | G31: https://i.postimg.cc/k5RnFLwg/cow-i.png | J31: 26 | K31: reaches into the box and pulls out......... a Cow Hood! https://i.postimg.cc/3Rqz5qKJ/cow-m.png
A32: Animals | B32: Horse | C32: AC15 | D32: Has a very fashionable mane. | F32: https://i.postimg.cc/kgpjz5Ns/horse-m.png | G32: https://i.postimg.cc/y8dQLRRW/horse-i.png | J32: 27 | K32: reaches into the box and pulls out......... a Horse Hood! https://i.postimg.cc/kgpjz5Ns/horse-m.png
A33: Animals | B33: Deer | C33: AC16 | D33: Loves you deer-ly. | F33: https://i.postimg.cc/zDR2fksZ/deer-m.png | G33: https://i.postimg.cc/Prs3vwHL/deer-i.png | J33: 28 | K33: reaches into the box and pulls out......... a Deer Hood! https://i.postimg.cc/zDR2fksZ/deer-m.png
A34: Animals | B34: Red Panda | C34: AC17 | D34: Fills you with raging teenager hormones. | F34: https://i.postimg.cc/SxYV2K7d/redpanda-m.png | G34: https://i.postimg.cc/1ztk1T1T/redpanda-i.png | J34: 29 | K34: reaches into the box and pulls out......... a Red Panda Hood! https://i.postimg.cc/SxYV2K7d/redpanda-m.png
A35: Animals | B35: Raccoon | C35: AC18 | D35: Makes you look vicious. | F35: https://i.postimg.cc/dVxqt5Qp/raccoon-m.png | G35: https://i.postimg.cc/BnC98nPP/raccoon-i.png | J35: 30 | K35: reaches into the box and pulls out......... a Raccoon Hood! https://i.postimg.cc/dVxqt5Qp/raccoon-m.png
A36: Animals | B36: Froggy, Crown | C36: AC19 | D36: 🎁 Reward. (solemnly) Ribbit. | F36: https://i.postimg.cc/Gm2LCWRv/froggy-crown-m.png | G36: https://i.postimg.cc/R0Vrwxws/froggy-crown-i.png | K36: has collected 9 hats from the Animal Hoods set and receives a Crowned Froggy hood and 50 Shards as a reward! https://i.postimg.cc/Gm2LCWRv/froggy-crown-m.png
A37: Animals | B37: Unicorn | C37: AC20 | D37: 🎁 Reward. Very magical! | F37: https://i.postimg.cc/26NVwVJc/unicorn-m.png | G37: https://i.postimg.cc/1t04Yy19/unicorn-i.png | K37: has collected 6 hats from the Basic set and receives a Basic cat colour of their choice and 50 Shards!
A38: April Fools 2022 | B38: Googly Eyes | C38: AD01 | D38: You can make anything silly with googly eyes. | F38: https://i.postimg.cc/nLkLTWS0/googlyeyes-m.png | G38: https://i.postimg.cc/7ZppjkXz/googlyeyes-i.png | K38: reaches into the box and pulls out......... some Googly Eyes! https://i.postimg.cc/nLkLTWS0/googlyeyes-m.png
A39: April Fools 2022 | B39: Jester Hat | C39: AD02 | D39: Jingles when you laugh. | F39: https://i.postimg.cc/jjK5HTcD/jester-a-m.png
A40: Shop Exclusive
...

Sheet Cats
A1: Set | B1: Name | C1: ID | D1: Description | E1: Cat URL | F1: Icon URL
A2: Starter | B2: Black | C2: *A01 | D2: Your typical house panther. | E2: https://i.postimg.cc/8581pQVw/black.png | F2: https://i.postimg.cc/13tRMrH0/black-i.png
A3: Starter | B3: White | C3: *A02 | D3: Likes to nap on blankets. | E3: https://i.postimg.cc/3w08Qrzd/white.png | F3: https://i.postimg.cc/tRZp3j4B/white-i.png
A4: Starter | B4: Grey | C4: *A03 | D4: Very playful. | E4: https://i.postimg.cc/zGczQHts/grey.png | F4: https://i.postimg.cc/mr6dbKMn/grey-i.png
A5: Starter | B5: Orange | C5: *A04 | D5: Extremely food motivated. | E5: https://i.postimg.cc/JnbRt6r8/orange.png | F5: https://i.postimg.cc/vTFSGcfH/orange-i.png
A6: Basic | B6: Tabby, Grey | C6: *B01 | D6: Likes to push things off tables. | E6: https://i.postimg.cc/q7KbKLmF/tabby-grey.png | F6: https://i.postimg.cc/gJPMHZQ2/tabby-grey-i.png
A7: Basic | B7: Tabby, Brown | C7: *B02 | D7: Will climb anything, people included. | E7: https://i.postimg.cc/x1MDHVjZ/tabby-brown.png | F7: https://i.postimg.cc/fT6QJRsX/tabby-brown-i.png
A8: Basic | B8: Tabby, Orange | C8: *B03 | D8: Never stops meowing. | E8: https://i.postimg.cc/257scdZF/tabby-orange.png | F8: https://i.postimg.cc/9MxvVW1D/tabby-orange-i.png
A9: Basic | B9: Tabby, Torbie | C9: *B04 | D9: Loves you... when they feel like it! | E9: https://i.postimg.cc/BZ70fCwm/tabby-torbie.png | F9: https://i.postimg.cc/9F4jmq6C/tabby-torbie-i.png
A10: Basic | B10: Calico, A | C10: *B05 | D10: ZOOMIES. | E10: https://i.postimg.cc/157rKpKC/calico-a.png | F10: https://i.postimg.cc/jSG6ptmy/calico-a-i.png
A11: Basic | B11: Calico, B | C11: *B06 | D11: Likes to nap upside down. | E11: https://i.postimg.cc/KYB7FChw/calico-b.png | F11: https://i.postimg.cc/Bn8c7XYq/calico-b-i.png
A12: Basic | B12: Calico, C | C12: *B07 | D12: Likes sunny windowsills. | E12: https://i.postimg.cc/SsGWY8sG/calico-c.png | F12: https://i.postimg.cc/nrcq4z9f/calico-c-i.png
A13: Basic | B13: Calico, D | C13: *B08 | D13: Prefers chicken over salmon. | E13: https://i.postimg.cc/pTvfdk2T/calico-d.png | F13: https://i.postimg.cc/kG1KfmW6/calico-d-i.png
A14: Basic | B14: Calico, E | C14: *B09 | E14: https://i.postimg.cc/85BKWgmW/calico-e.png
A15: Basic | B15: Calico, F | C15: *B10 | E15: https://i.postimg.cc/QC86JYfz/calico-f.png
A16: Basic | B16: Calico, G | C16: *B11 | E16: https://i.postimg.cc/Ssp1JxCk/calico-g.png
A17: Basic | B17: Calico, H | C17: *B12 | E17: https://i.postimg.cc/FKSnrLfT/calico-h.png
A18: Shop Exclusive | B18: Galaxy | C18: *C01 | D18: Twinkles. | E18: https://i.postimg.cc/JzvYtgQJ/galaxy.png | F18: https://i.postimg.cc/P5PFXh1T/galaxy-i.png
A19: Shop Exclusive | B19: Glass | C19: *C02 | D19: Tinkles. | E19: https://i.postimg.cc/8kXzS7gb/glass.png
A20: Shop Exclusive | B20: Meadow | C20: *C03 | D20: Smells like fresh grass. | E20: https://i.postimg.cc/4NKNNXJR/meadow.png
A21: Shop Exclusive | B21: Magma | C21: *C04 | D21: Hot, hot, HOT! | E21: https://i.postimg.cc/gj7zqTH7/magma.png

Sheet Shop
A1: Type | B1: Set | C1: Name | D1: ID | E1: Description | F1: Image URL | G1: Icon URL | H1: Available | I1: Cost
A2: Cat | B2: =Cats!$A$6:Cats!$F$6 -> Basic | C2: Tabby, Grey | D2: *B01 | E2: Likes to push things off tables. | F2: https://i.postimg.cc/q7KbKLmF/tabby-grey.png | G2: https://i.postimg.cc/gJPMHZQ2/tabby-grey-i.png | H2: =true -> TRUE | I2: 25
A3: Cat | B3: =Cats!$A$7:Cats!$F$7 -> Basic | C3: Tabby, Brown | D3: *B02 | E3: Will climb anything, people included. | F3: https://i.postimg.cc/x1MDHVjZ/tabby-brown.png | G3: https://i.postimg.cc/fT6QJRsX/tabby-brown-i.png | I3: 25
A4: Cat | B4: =Cats!$A$8:Cats!$F$8 -> Basic | C4: Tabby, Orange | D4: *B03 | E4: Never stops meowing. | F4: https://i.postimg.cc/257scdZF/tabby-orange.png | G4: https://i.postimg.cc/9MxvVW1D/tabby-orange-i.png | I4: 25
A5: Cat | B5: =Cats!$A$9:Cats!$F$9 -> Basic | C5: Tabby, Torbie | D5: *B04 | E5: Loves you... when they feel like it! | F5: https://i.postimg.cc/BZ70fCwm/tabby-torbie.png | G5: https://i.postimg.cc/9F4jmq6C/tabby-torbie-i.png | I5: 25
A6: Cat | B6: =Cats!$A$18:Cats!$F$18 -> Shop Exclusive | C6: Galaxy | D6: *C01 | E6: Twinkles. | F6: https://i.postimg.cc/JzvYtgQJ/galaxy.png | G6: https://i.postimg.cc/P5PFXh1T/galaxy-i.png | I6: 200
A7: Cat | C7: =Cats!$B$19:Cats!$F$19 -> Glass | D7: *C02 | E7: Tinkles. | F7: https://i.postimg.cc/8kXzS7gb/glass.png | I7: 200
A8: Cat | C8: =Cats!$B$20:Cats!$F$20 -> Meadow | D8: *C03 | E8: Smells like fresh grass. | F8: https://i.postimg.cc/4NKNNXJR/meadow.png | I8: 200
A9: Cat | C9: =Cats!$B$21:Cats!$F$21 -> Magma | D9: *C04 | E9: Hot, hot, HOT! | F9: https://i.postimg.cc/gj7zqTH7/magma.png | I9: 200

Sheet User Template
B2: Laviee
J3: Currency | N3: 100
J5: =IMAGE("https://i.postimg.cc/3R08Xr3g/laviee-big.png", 3)
J6: =IMAGE("https://i.postimg.cc/13tRMrH0/black-i.png",3) | M6: =IMAGE("https://i.postimg.cc/htfgVPDp/teddy-ribbon-i.png", 3)
B8: Cat Collection
B11: Hat Collection
B12: =IF(C13, image(Hats!$F$2, 3), ) | F12: =IMAGE(Hats!$F$3, 3) | J12: =IF(K13, image(Hats!$F$4, 3), ) | N12: =IMAGE(Hats!$F$5, 3) | R12: =IF(S13, image(Hats!$F$6, 3), ) | V12: =IF(W13, image(Hats!$F$7, 3), )
B13: =Hats!$C$2 -> AA01 | C13: 0 | F13: =Hats!$C$3 -> AA02 | G13: 0 | J13: =Hats!$C$4 -> AA03 | K13: 0 | N13: =Hats!$C$5 -> AA04 | O13: 0 | R13: =Hats!$C$6 -> AB01 | S13: 0 | V13: =Hats!$C$7 -> AB02 | W13: 0
B15: =IF(C16, image(Hats!$F$8, 3), ) | F15: =IF(G16, image(Hats!$F$9, 3), ) | J15: =IF(K16, image(Hats!$F$10, 3), ) | N15: =IF(O16, image(Hats!$F$11, 3), ) | R15: =IF(S16, image(Hats!$F$18, 3), ) | V15: =IF(W16, image(Hats!$F$19, 3), )
B16: =Hats!$C$8 -> AB03 | C16: 0 | F16: =Hats!$C$9 -> AB04 | G16: 0 | J16: =Hats!$C$10 -> AB05 | K16: 0 | N16: =Hats!$C$11 -> AB06 | O16: 0 | R16: =Hats!$C$22 -> AC05 | S16: 1 | V16: =Hats!$C$19 -> AC02 | W16: 0
